Workbook

Sheet Cover
B11: Fresher Full-Stack Development
B13: PYTHON PROGRAMMING SYLLABUS
F17: Document Code | I17: 26e-BM/HR/HDCV/FSOFT
F18: Version | I18: 2.0
F19: Effective Date | I19: 24/04/2020

Sheet Syllabus
A1: =C3&" "&"Syllabus" -> Azure AI Fundamentals Syllabus
A2: 1 | B2: Technical Group | C2: AI
A3: 2 | B3: Topic Name | C3: Azure AI Fundamentals
A4: 3 | B4: Topic Code | C4: AI-900
A5: 4 | B5: Version | C5: 1
A6: 5 | B6: Training Audience | C6: - AI beginners (no programming experience required) - IT Professionals transitioning to AI field - Business Analysts, Product Managers who need to understand AI - Developers, Data Scientists seeking foundational certification - Anyone wanting to understand AI and prepare for AI-900 certification
A7: 6 | B7: Course Objectives | C7: Provide foundational knowledge of Artificial Intelligence (AI) and Azure AI services, preparing students for the Microsoft Certified: Azure AI Fundamentals (AI-900) certification exam.
C8: Name | D8: Code | E8: Description
C9: Understand fundamental AI concepts | D9: K1AI | E9: Demonstrate the ability to explain core Artificial Intelligence concepts, key terminologies, major application areas, and the role of AI in digital transformation initiatives.
C10: Understand fundamental Machine Learning concepts | D10: K2AI | E10: Demonstrate the ability to explain essential Machine Learning paradigms, learning workflows, data requirements, and commonly used evaluation metrics.
C11: Understand Azure AI services and capabilities | D11: K3AI | E11: Identify and describe core Azure AI services, their primary functions, and typical enterprise use cases.
C12: Select appropriate Machine Learning approaches | D12: H1AI | E12: Analyze problem statements and select suitable Machine Learning models aligned with business and technical requirements.
C13: Select appropriate Azure AI services | D13: H2AI | E13: Evaluate AI scenarios and recommend appropriate Azure AI services to design effective and scalable solutions.
C14: Make informed AI solution decisions | D14: H3AI | E14: Assess real-world situations and justify the selection of Azure AI services based on constraints, risks, and expected outcomes.
C15: Apply Responsible AI principles | D15: H4AI | E15: Integrate Responsible AI principles (fairness, reliability, security, privacy, transparency, accountability) into the design and deployment of AI solutions.
C16: Achieve AI-900 certification readiness | D16: H5AI | E16: Demonstrate readiness to sit for and successfully obtain the Microsoft Azure AI Fundamentals (AI-900) certification.
C17: In details, after completing the course, trainees will: 1. Fundamental AI Concepts & Azure AI Overview - Define and distinguish AI, Machine Learning, Deep Learning - Understand AI workload types: Computer Vision, NLP, Conversational AI, Generative AI - Master Microsoft's 6 Responsible AI principles - Identify real-world AI applications in enterprise - Distinguish Azure AI Services categories and use cases - Choose appropriate services for scenarios - Deploy and manage AI services on Azure 2. Machine Learning Fundamentals - Distinguish Supervised, Unsupervised, and Reinforcement Learning - Understand ML lifecycle: Data → Training → Evaluation → Deployment - Apply model evaluation metrics: Accuracy, Precision, Recall, F1, RMSE, R² - Identify and address overfitting, underfitting 3. Computer Vision, NLP, Generative AI Workloads - Define and distinguish Computer Vision, NLP workloads - Choose appropriate solutions for real-world problems - Implement Computer Vision tasks using Azure Vision Services - Implement NLP tasks using Azure Language Services 4. Responsible AI Principles - Understand importance of Responsible AI - Apply Microsoft's 6 Responsible AI principles in projects - Use Azure tools for fairness, interpretability, transparency - Identify and mitigate bias in AI models - Ensure privacy, security, and accountability in AI solutions 5. Certification Readiness - Master 100% of AI-900 exam content - Familiarize with exam question formats - Confidently achieve score ≥700/1000 (passing score)
A18: 7 | B18: Topic Outline | C18: 1. Introduction to AI 2. Azure AI Fundamentals 3. Machine Learning Fundamentals 4. Azure Machine Learning Fundamentals 5. Natural Language Processing 6. Computer Vision 7. Generative AI 8. Responsible AI
A19: 8 | B19: Time Allocation | C19: Concept/Lecture | D19: =ScheduleDetail!H52 -> 0.22959184 | E19: Concepts, theory | F19: 8 sessions
C20: Assignment/Lab | D20: =ScheduleDetail!H53 -> 0.43877551 | E20: Assignment, Lab
C21: Guides/Review | D21: =ScheduleDetail!H54 -> 0.15816327 | E21: Quiz, assignment review Assignment guides
C22: Seminar/Workshop | D22: =ScheduleDetail!H57 -> 0.15816327 | E22: Seminar, Workshop
C23: Class Meeting | D23: =ScheduleDetail!H58 -> 0 | E23: Daily class meeting
C24: Audit | D24: =ScheduleDetail!H55 -> 0 | E24: Final quiz
C25: Review mock final | D25: =ScheduleDetail!H56 -> 0.015306122 | E25: Review Mock Project
A26: 9 | B26: Training Materials & Environments | C26: Text book | D26: 1. Speech and Language Processing.pdf 2. Foundations of Statistical Natural Language Processing.pdf 3. Pattern Recognition and Machine Learning.pdf 4. Neural Network Methods in Natural Language Processing.pdf 5. Practical Natural Language Processing.pdf 6. AI_RMF_Playbook.pdf 7. Chip_Huyen_Designing_Machine_Learning_Systems_An_Iterative_Process.pdf 8. Dive into Deep Learning.pdf 9. Machine Learning Yearning-VN.pdf 10. Natural Language Processing with Python.pdf 11. Neural-Networks-Overview-365-Data-Science-Course Notes.pdf 12. storytelling-with-data-cole-nussbaumer-knaflic.pdf
C27: References | D27: - Microsoft Learn: https://learn.microsoft.com/training/paths/get-started-with-artificial-intelligence-on-azure/ - Azure Portal: https://portal.azure.com - Practice Assessment for Exam AI-900: Microsoft Azure AI Fundamentals: https://learn.microsoft.com/en-us/credentials/certifications/azure-ai-fundamentals/practice/assessment?assessment-type=practice&assessmentId=26&practice-assessment-type=certification - Linkedin (theory): https://www.linkedin.com/learning/microsoft-azure-ai-fundamentals-ai-900-cert-prep-by-microsoft-press?u=441943138 - Linkedin (Practice Assessment): https://www.linkedin.com/learning/practice-exam-1-for-azure-ai-fundamentals-ai-900?u=441943138 - Linkedin (Practice Assessment): https://www.linkedin.com/learning/practice-exam-2-for-azure-ai-fundamentals-ai-900?u=441943138
C28: Technical requirements | D28: N/A
A29: 10 | B29: Assessment Scheme | C29: Mini Test | D29: 3 | E29: 0.3
C30: Assignments | D30: 1 | E30: 0.7 | F30: Online practice assessment from Microsoft.
C31: Pass Criteria | D31: 7
A32: 11 | B32: Training Delivery Principles | C32: Trainees | D32: TBD
C33: Trainer | D33: Trainer has strong knowledge of AI and Azure and holds the Azure AI Fundamentals certification.
C34: Training | D34: - Trainee do self-learning and do practice - Trainee be required to complete online learning according to MOOC links provided - Trainer supports answering questions, guiding exercises and review
C35: Re-Test | D35: 0
C36: Marking
C37: Waiver Criteria | D37: Students pass the audit Trainer Audit: rank B
C38: Others | D38: N/A

Sheet ScheduleDetail
A1: =Syllabus!C3 & " - Training Schedule" -> Azure AI Fundamentals - Training Schedule
A2: Training Unit/Chapter | C2: Sessions | D2: Content | E2: Learning Objectives | F2: Delivery Type | G2: Duration (mins) | H2: Training Format | I2: Training Materials / Logistics & General Notes (Required, For Reference, etc.)
B3: Workshop #0: Course Introduction | C3: 1 | D3: - Introduction to the course content - Introduction to learning materials and resources - Guidance on learning methods and study approach - Overview of the learning roadmap - Overview of the AI-900 certification exam | E3: H5AI | F3: Seminar/Workshop | G3: 30 | H3: Virtual training | I3: Slide: 0_Course_Introduction
B4: Overview of AI concepts | C4: 1 | D4: Overview of AI concepts | E4: K1AI | F4: Concept/Lecture | G4: 45 | H4: Online | I4: https://learn.microsoft.com/en-us/training/modules/get-started-ai-fundamentals/
B5: Workshop #1: Introduction to AI | C5: 1 | D5: - Define Artificial Intelligence (AI) and its importance - Distinguish between AI, Machine Learning (ML), and Deep Learning (DL) - Identify common AI workloads and real-world use cases - Recognize the impact and potential of AI in business and society | E5: K1AI | F5: Seminar/Workshop | G5: 45 | H5: Virtual training | I5: Slide: 1_Introduction_to_AI
B6: Workshop #1: Introduction to AI | C6: 1 | D6: - Define Artificial Intelligence (AI) and its importance - Distinguish between AI, Machine Learning (ML), and Deep Learning (DL) - Identify common AI workloads and real-world use cases - Recognize the impact and potential of AI in business and society | E6: K1AI | F6: Guides/Review | G6: 45 | H6: Virtual training | I6: Slide: 1_Introduction_to_AI
B7: Sefl-study: Introduction to AI | C7: 1 | D7: Sefl-study: Introduction to AI | E7: K1AI | F7: Assignment/Lab | G7: 120 | H7: Offline | I7: 1. Tài liệu chính thức từ Microsoft: - Microsoft Learn: https://learn.microsoft.com/training/paths/get-started-with-artificial-intelligence-on-azure/ - Azure Portal dùng để thực hành (cần chờ tài khoản từ IT cấp, hoặc tự tạo tài khoản cá nhân, sử dụng tài khoản sinh viên nếu có): https://portal.azure.com - Link bài Practice Assessment for Exam AI-900: Microsoft Azure AI Fundamentals: https://learn.microsoft.com/en-us/credentials/certifications/azure-ai-fundamentals/practice/assessment?assessment-type=practice&assessmentId=26&practice-assessment-type=certification 2. Link khóa học online: - Linkedin (lý thuyết): https://www.linkedin.com/learning/microsoft-azure-ai-fundamentals-ai-900-cert-prep-by-microsoft-press?u=441943138 - Linkedin (thi thử): https://www.linkedin.com/learning/practice-exam-1-for-azure-ai-fundamentals-ai-900?u=441943138 - Linkedin (thi thử): https://www.linkedin.com/learning/practice-exam-2-for-azure-ai-fundamentals-ai-900?u=441943138 - Youtube: search với từ khóa "AI-900" 3. Tài liệu nội bộ khóa học: https://fptsoftware362-my.sharepoint.com/:f:/r/personal/thaott29_fpt_com/Documents/Kh%C3%B3a%20h%E1%BB%8Dc%20Azure%20AI%20Fundamentals%20(AI-900)/T%C3%A0i%20li%E1%BB%87u%20kh%C3%B3a%20h%E1%BB%8Dc?csf=1&web=1&e=fPhsta - Slides: Bản HTML (trong các buổi workshop) và bản PDF (xuất từ HTML) - Text books: eBook về các chủ đề có liên quan, dành cho bạn nào muốn tìm hiểu sâu cho từng vấn đề cụ thể - Notebooks: File tóm tắt sau mỗi workshop - Dumps: Bộ câu hỏi luyện tập tương tự đề thi thật
B8: Get started with AI in Microsoft Foundry | C8: 2 | D8: Get started with AI in Microsoft Foundry | E8: K1AI | F8: Concept/Lecture | G8: 45 | H8: Online | I8: https://learn.microsoft.com/en-gb/training/modules/get-started-ai-in-foundry/
B9: Lab: Get started with AI in Microsoft Foundry | C9: 2 | D9: Get started with AI in Microsoft Foundry | E9: H1AI | F9: Assignment/Lab | G9: 60 | H9: Online | I9: https://learn.microsoft.com/en-gb/training/modules/get-started-ai-in-foundry/
B10: Workshop #2: Azure AI Fundamentals | C10: 2 | D10: - Identify and describe the main Azure AI services and their use cases - Understand how to choose the right AI service for different business scenarios | E10: K1AI | F10: Seminar/Workshop | G10: 60 | H10: Virtual training | I10: Slide: 2_Azure_AI_Fundamentals
B11: Workshop #2: Azure AI Fundamentals | C11: 2 | D11: - Identify and describe the main Azure AI services and their use cases - Understand how to choose the right AI service for different business scenarios | E11: K1AI | F11: Guides/Review | G11: 60 | H11: Virtual training | I11: Slide: 2_Azure_AI_Fundamentals
B12: Sefl-study: Azure AI Fundamentals | C12: 2 | D12: Sefl-study: Azure AI Fundamentals | E12: H1AI | F12: Assignment/Lab | G12: 120 | H12: Offline | I12: 1. Tài liệu chính thức từ Microsoft: - Microsoft Learn: https://learn.microsoft.com/training/paths/get-started-with-artificial-intelligence-on-azure/ - Azure Portal dùng để thực hành (cần chờ tài khoản từ IT cấp, hoặc tự tạo tài khoản cá nhân, sử dụng tài khoản sinh viên nếu có): https://portal.azure.com - Link bài Practice Assessment for Exam AI-900: Microsoft Azure AI Fundamentals: https://learn.microsoft.com/en-us/credentials/certifications/azure-ai-fundamentals/practice/assessment?assessment-type=practice&assessmentId=26&practice-assessment-type=certification 2. Link khóa học online: - Linkedin (lý thuyết): https://www.linkedin.com/learning/microsoft-azure-ai-fundamentals-ai-900-cert-prep-by-microsoft-press?u=441943138 - Linkedin (thi thử): https://www.linkedin.com/learning/practice-exam-1-for-azure-ai-fundamentals-ai-900?u=441943138 - Linkedin (thi thử): https://www.linkedin.com/learning/practice-exam-2-for-azure-ai-fundamentals-ai-900?u=441943138 - Youtube: search với từ khóa "AI-900" 3. Tài liệu nội bộ khóa học: https://fptsoftware362-my.sharepoint.com/:f:/r/personal/thaott29_fpt_com/Documents/Kh%C3%B3a%20h%E1%BB%8Dc%20Azure%20AI%20Fundamentals%20(AI-900)/T%C3%A0i%20li%E1%BB%87u%20kh%C3%B3a%20h%E1%BB%8Dc?csf=1&web=1&e=fPhsta - Slides: Bản HTML (trong các buổi workshop) và bản PDF (xuất từ HTML) - Text books: eBook về các chủ đề có liên quan, dành cho bạn nào muốn tìm hiểu sâu cho từng vấn đề cụ thể - Notebooks: File tóm tắt sau mỗi workshop - Dumps: Bộ câu hỏi luyện tập tương tự đề thi thật
B13: Introduction to machine learning concepts | C13: 3 | D13: Introduction to machine learning concepts | E13: K1AI | F13: Concept/Lecture | G13: 45 | H13: Online | I13: https://learn.microsoft.com/en-gb/training/modules/fundamentals-machine-learning/
B14: Workshop #3: Machine Learning Fundamentals | C14: 3 | D14: - Define what Machine Learning is and why it matters - Differentiate supervised, unsupervised, and other learning types - Identify common machine learning problem types and real-world examples - Explain the machine learning lifecycle and best practices - See how these ML concepts fit into the overall Azure AI Fundamentals (AI-900) exam scope | E14: K2AI | F14: Seminar/Workshop | G14: 60 | H14: Virtual training | I14: Slide: 3_Machine_Learning_Fundamentals
... B50: Final Assessment | C50: 8 | D50: Final Assessment | E50: H5AI | F50: Final Mock | G50: 45 | H50: Online | I50: https://learn.microsoft.com/en-us/credentials/certifications/azure-ai-fundamentals/practice/assessment?assessment-type=practice&assessmentId=26&practice-assessment-type=certification
F52: Concept/Lecture | G52: =SUMIF(F$4:F$50,F52,G$4:G$50) -> 675 | H52: =G52/$G$59 -> 0.22959184
F53: Assignment/Lab | G53: =SUMIF(F$4:F$50,F53,G$4:G$50) -> 1290 | H53: =G53/$G$59 -> 0.43877551
F54: Guides/Review | G54: =SUMIF(F$4:F$50,F54,G$4:G$50) -> 465 | H54: =G54/$G$59 -> 0.15816327
F55: Final Audit | G55: =SUMIF(F$4:F$50,F55,G$4:G$50) -> 0 | H55: =G55/$G$59 -> 0
F56: Final Mock | G56: =SUMIF(F$4:F$50,F56,G$4:G$50) -> 45 | H56: =G56/$G$59 -> 0.015306122
F57: Seminar/Workshop | G57: =SUMIF(F$4:F$50,F57,G$4:G$50) -> 465 | H57: =G57/$G$59 -> 0.15816327
F58: Class Meeting | G58: =SUMIF(F$4:F$50,F58,G$4:G$50) -> 0 | H58: =G58/$G$59 -> 0
F59: Total | G59: =SUM(G52:G58) -> 2940 | H59: =SUM(H52:H58) -> 1

Sheet Author and Rec of Changes
A1: AUTHORSHIP
B2: Role | C2: Name | D2: Account | E2: Unit | F2: Notes
B3: Creator | C3: Trinh Ba Tu | D3: TuTB | E3: FSA.NLS
B4: Reviewer
B5: Approver
A6: RECORD OF CHANGES
A7: *A - Added M - Modified D - Deleted
B9: Date | C9: Changes | D9: A* M, D | E9: Contents | F9: Version
B10: 45951 | C10: Create | D10: A* | E10: New Syllabus | F10: 0.1
B11: 45955 | C11: Update | D11: M | E11: CongDX update format workshop and Practice | F11: 0.2

Sheet Cost Estimate
A1: 1 | B1: Cost estimate
B3: Service | C3: Typical Usage per Month | D3: Reference Price (USD) | E3: Estimated Monthly Cost per Student | F3: Rationale / Estimation Basis
B4: Azure Machine Learning – Compute Cluster (Automated ML) | C4: Small cluster, ~1–2 hours | D4: ~$0.15 – $0.20 / hour | E4: 0.3 | F4: Automatically provisioned during Automated ML experiments
B5: Azure App Service (B1) | C5: 1 app, ~20 hours | D5: ~$0.075/hour | E5: 1.5 | F5: Used to host demo web/API calling Azure AI services; only active during lab hours
B6: Azure Storage (Blob – Hot) | C6: ~10 GB | D6: ~$0.0184/GB/month | E6: 0.2 | F6: Stores datasets, images, and outputs for custom model training and inference
B7: Azure AI Language (Prebuilt – F0) | C7: Sentiment, NER demo | D7: Free tier | E7: 0 | F7: Used for AI-900 NLP prebuilt labs; free tier sufficient
B8: Azure AI Vision (Prebuilt – F0) | C8: Image analysis demo | D8: Free tier | E8: 0 | F8: Demonstrates image analysis and OCR basics
B9: Azure AI Speech (F0) | C9: Speech-to-text demo | D9: Free tier | E9: 0 | F9: Demonstrates speech recognition with limited usage
B10: Azure AI Document Intelligence (F0) | C10: Read / Layout demo | D10: Free tier | E10: 0 | F10: Demonstrates document text extraction
B11: Azure AI Language – Custom (S0) | C11: 1 project, 1–2 training jobs | D11: ~$1 / 1k records (est.) | E11: 3 | F11: Required for training custom text classification or NER models; not supported in F0
B12: Azure AI Vision – Custom Vision (S0) | C12: 1 project, 1–2 training jobs | D12: ~$2 / training hour | E12: 2 | F12: Used to train a custom image recognition model with small datasets
B13: Azure Functions (Consumption) | C13: <=10k executions | D13: Free grant | E13: 0 | F13: Used as lightweight middleware or API glue
B14: Azure Monitor / Log Analytics | C14: ~150 MB logs | D14: ~$2.76/GB | E14: 0.4 | F14: Used for monitoring and debugging during labs
B15: Azure Application Insights | C15: Basic telemetry | D15: Included | E15: 0 | F15: Tracks application performance and requests
... B18: Microsoft Entra ID (Azure AD) | C18: User & role management | D18: Free | E18: 0 | F18: Used for identity and role-based access control
B19: Total | E19: =SUM(E4:E18) -> 7.41
B20: Buffer | E20: 10
B21: Number of student: | E21: 33
B22: Number of trainer: | E22: 1
B23: Total estimate: | E23: =E20*(E21+E22) -> 340
A25: 2 | B25: Important Notes
A27: a | B27: This cost estimate is calculated on a per-student basis.
B28: For each training class, Azure service provisioning must be requested for one instructor and the exact number of participating students to ensure accurate cost planning and resource allocation.
A30: b | B30: Instructors must guide and regularly remind students to stop or delete Azure resources when they are not in use.
B31: Leaving services running continuously (24/7) may lead to unnecessary and unexpected costs.
A33: c | B33: A spending cap should be configured for each student subscription, with an upper limit of $10.
B34: This ensures that individual costs remain within an acceptable and controlled range during hands-on practice.
A36: d | B36: This cost estimation is based on pricing available as of January 2026.
B37: In case the cloud service provider updates or adjusts pricing, the estimate should be reviewed and updated accordingly.

Sheet DV-IDENTITY-0
A1: =IF(Syllabus!1:1,"AAAAAH7b/wA=",0) -> #VALUE! | B1: =AND(Syllabus!#REF!,"AAAAAH7b/wE=") -> #REF! | C1: =AND(Syllabus!B1,"AAAAAH7b/wI=") -> #VALUE! | D1: =AND(Syllabus!C1,"AAAAAH7b/wM=") -> #VALUE! | E1: =AND(Syllabus!D1,"AAAAAH7b/wQ=") -> #VALUE! | F1: =AND(Syllabus!E1,"AAAAAH7b/wU=") -> #VALUE! | G1: =AND(Syllabus!F1,"AAAAAH7b/wY=") -> #VALUE! | H1: =AND(Syllabus!G1,"AAAAAH7b/wc=") -> #VALUE! | I1: =IF(Syllabus!#REF!,"AAAAAH7b/wg=",0) -> #REF! | J1: =AND(Syllabus!#REF!,"AAAAAH7b/wk=") -> #REF! | K1: =AND(Syllabus!#REF!,"AAAAAH7b/wo=") -> #REF! | L1: =AND(Syllabus!#REF!,"AAAAAH7b/ws=") -> #REF! | M1: =AND(Syllabus!#REF!,"AAAAAH7b/ww=") -> #REF! | N1: =AND(Syllabus!#REF!,"AAAAAH7b/w0=") -> #REF! | O1: =AND(Syllabus!#REF!,"AAAAAH7b/w4=") -> #REF! | P1: =AND(Syllabus!#REF!,"AAAAAH7b/w8=") -> #REF! | Q1: =IF(Syllabus!2:2,"AAAAAH7b/xA=",0) -> 0 | R1: =AND(Syllabus!A2,"AAAAAH7b/xE=") -> TRUE | S1: =AND(Syllabus!B2,"AAAAAH7b/xI=") -> #VALUE! | T1: =AND(Syllabus!C2,"AAAAAH7b/xM=") -> #VALUE! | U1: =AND(Syllabus!D2,"AAAAAH7b/xQ=") -> #VALUE! | V1: =AND(Syllabus!E2,"AAAAAH7b/xU=") -> #VALUE! | W1: =AND(Syllabus!F2,"AAAAAH7b/xY=") -> #VALUE! | X1: =AND(Syllabus!G2,"AAAAAH7b/xc=") -> #VALUE! | Y1: =IF(Syllabus!4:4,"AAAAAH7b/xg=",0) -> 0 | Z1: =AND(Syllabus!A4,"AAAAAH7b/xk=") -> TRUE | AA1: =AND(Syllabus!B4,"AAAAAH7b/xo=") -> #VALUE! | AB1: =AND(Syllabus!C4,"AAAAAH7b/xs=") -> #VALUE! | AC1: =AND(Syllabus!D4,"AAAAAH7b/xw=") -> #VALUE! | AD1: =AND(Syllabus!E4,"AAAAAH7b/x0=") -> #VALUE! | AE1: =AND(Syllabus!F4,"AAAAAH7b/x4=") -> #VALUE! | AF1: =AND(Syllabus!G4,"AAAAAH7b/x8=") -> #VALUE! | AG1: =IF(Syllabus!5:5,"AAAAAH7b/yA=",0) -> 0 | AH1: =AND(Syllabus!A5,"AAAAAH7b/yE=") -> TRUE | AI1: =AND(Syllabus!B5,"AAAAAH7b/yI=") -> #VALUE! | AJ1: =AND(Syllabus!C5,"AAAAAH7b/yM=") -> TRUE | AK1: =AND(Syllabus!D5,"AAAAAH7b/yQ=") -> #VALUE! | AL1: =AND(Syllabus!E5,"AAAAAH7b/yU=") -> #VALUE! | AM1: =AND(Syllabus!F5,"AAAAAH7b/yY=") -> #VALUE! | AN1: =AND(Syllabus!G5,"AAAAAH7b/yc=") -> #VALUE! | AO1: =IF(Syllabus!6:6,"AAAAAH7b/yg=",0) -> 0 | AP1: =AND(Syllabus!A6,"AAAAAH7b/yk=") -> TRUE | AQ1: =AND(Syllabus!B6,"AAAAAH7b/yo=") -> #VALUE! | AR1: =AND(Syllabus!C6,"AAAAAH7b/ys=") -> #VALUE! | AS1: =AND(Syllabus!D6,"AAAAAH7b/yw=") -> #VALUE! | AT1: =AND(Syllabus!E6,"AAAAAH7b/y0=") -> #VALUE! | AU1: =AND(Syllabus!F6,"AAAAAH7b/y4=") -> #VALUE! | AV1: =AND(Syllabus!G6,"AAAAAH7b/y8=") -> #VALUE! | AW1: =IF(Syllabus!7:7,"AAAAAH7b/zA=",0) -> 0 | AX1: =AND(Syllabus!A7,"AAAAAH7b/zE=") -> TRUE | AY1: =AND(Syllabus!B7,"AAAAAH7b/zI=") -> #VALUE! | AZ1: =AND(Syllabus!C7,"AAAAAH7b/zM=") -> #VALUE! | BA1: =AND(Syllabus!D7,"AAAAAH7b/zQ=") -> #VALUE! | BB1: =AND(Syllabus!E7,"AAAAAH7b/zU=") -> #VALUE! | BC1: =AND(Syllabus!F7,"AAAAAH7b/zY=") -> #VALUE! | BD1: =AND(Syllabus!G7,"AAAAAH7b/zc=") -> #VALUE! | BE1: =IF(Syllabus!8:8,"AAAAAH7b/zg=",0) -> 0 | BF1: =AND(Syllabus!A8,"AAAAAH7b/zk=") -> #VALUE! | BG1: =AND(Syllabus!B8,"AAAAAH7b/zo=") -> #VALUE! | BH1: =AND(Syllabus!C8,"AAAAAH7b/zs=") -> #VALUE! | BI1: =AND(Syllabus!D8,"AAAAAH7b/zw=") -> #VALUE! | BJ1: =AND(Syllabus!E8,"AAAAAH7b/z0=") -> #VALUE! | BK1: =AND(Syllabus!F8,"AAAAAH7b/z4=") -> #VALUE! | BL1: =AND(Syllabus!G8,"AAAAAH7b/z8=") -> #VALUE! | BM1: =IF(Syllabus!9:9,"AAAAAH7b/0A=",0) -> 0 | BN1: =AND(Syllabus!A9,"AAAAAH7b/0E=") -> #VALUE! | BO1: =AND(Syllabus!B9,"AAAAAH7b/0I=") -> #VALUE! | BP1: =AND(Syllabus!C9,"AAAAAH7b/0M=") -> #VALUE! | BQ1: =AND(Syllabus!D9,"AAAAAH7b/0Q=") -> #VALUE! | BR1: =AND(Syllabus!E9,"AAAAAH7b/0U=") -> #VALUE! | BS1: =AND(Syllabus!F9,"AAAAAH7b/0Y=") -> #VALUE! | BT1: =AND(Syllabus!G9,"AAAAAH7b/0c=") -> #VALUE! | BU1: =IF(_xlfn.SINGLE(Syllabus!#REF!),"AAAAAH7b/0g=",0) -> #REF! | BV1: =AND(Syllabus!#REF!,"AAAAAH7b/0k=") -> #REF! | BW1: =AND(Syllabus!#REF!,"AAAAAH7b/0o=") -> #REF! | BX1: =AND(Syllabus!#REF!,"AAAAAH7b/0s=") -> #REF! | BY1: =AND(Syllabus!#REF!,"AAAAAH7b/0w=") -> #REF! | BZ1: =AND(Syllabus!#REF!,"AAAAAH7b/00=") -> #REF! | CA1: =AND(Syllabus!#REF!,"AAAAAH7b/04=") -> #REF! | CB1: =AND(Syllabus!#REF!,"AAAAAH7b/08=") -> #REF! | CC1: =IF(_xlfn.SINGLE(Syllabus!#REF!),"AAAAAH7b/1A=",0) -> #REF! | CD1: =AND(Syllabus!#REF!,"AAAAAH7b/1E=") -> #REF! | CE1: =AND(Syllabus!#REF!,"AAAAAH7b/1I=") -> #REF! | CF1: =AND(Syllabus!#REF!,"AAAAAH7b/1M=") -> #REF! | CG1: =AND(Syllabus!#REF!,"AAAAAH7b/1Q=") -> #REF! | CH1: =AND(Syllabus!#REF!,"AAAAAH7b/1U=") -> #REF! | CI1: =AND(Syllabus!#REF!,"AAAAAH7b/1Y=") -> #REF! | CJ1: =AND(Syllabus!#REF!,"AAAAAH7b/1c=") -> #REF! | CK1: =IF(Syllabus!18:18,"AAAAAH7b/1g=",0) -> 0 | CL1: =AND(Syllabus!A18,"AAAAAH7b/1k=") -> TRUE | CM1: =AND(Syllabus!B18,"AAAAAH7b/1o=") -> #VALUE! | CN1: =AND(Syllabus!C18,"AAAAAH7b/1s=") -> #VALUE! | CO1: =AND(Syllabus!D18,"AAAAAH7b/1w=") -> #VALUE! | CP1: =AND(Syllabus!E18,"AAAAAH7b/10=") -> #VALUE! | CQ1: =AND(Syllabus!F18,"AAAAAH7b/14=") -> #VALUE! | CR1: =AND(Syllabus!G18,"AAAAAH7b/18=") -> #VALUE! | CS1: =IF(Syllabus!19:19,"AAAAAH7b/2A=",0) -> 0 | CT1: =AND(Syllabus!A19,"AAAAAH7b/2E=") -> TRUE | CU1: =AND(Syllabus!B19,"AAAAAH7b/2I=") -> #VALUE! | CV1: =AND(Syllabus!C19,"AAAAAH7b/2M=") -> #VALUE! | CW1: =AND(Syllabus!D19,"AAAAAH7b/2Q=") -> TRUE | CX1: =AND(Syllabus!E19,"AAAAAH7b/2U=") -> #VALUE! | CY1: =AND(Syllabus!F19,"AAAAAH7b/2Y=") -> #VALUE! | CZ1: =AND(Syllabus!G19,"AAAAAH7b/2c=") -> #VALUE! | DA1: =IF(Syllabus!20:20,"AAAAAH7b/2g=",0) -> 0 | DB1: =AND(Syllabus!A20,"AAAAAH7b/2k=") -> #VALUE! | DC1: =AND(Syllabus!B20,"AAAAAH7b/2o=") -> #VALUE! | DD1: =AND(Syllabus!C20,"AAAAAH7b/2s=") -> #VALUE! | DE1: =AND(Syllabus!D20,"AAAAAH7b/2w=") -> TRUE | DF1: =AND(Syllabus!E20,"AAAAAH7b/20=") -> #VALUE! | DG1: =AND(Syllabus!F20,"AAAAAH7b/24=") -> #VALUE! | DH1: =AND(Syllabus!G20,"AAAAAH7b/28=") -> #VALUE! | DI1: =IF(Syllabus!21:21,"AAAAAH7b/3A=",0) -> 0 | DJ1: =AND(Syllabus!A21,"AAAAAH7b/3E=") -> #VALUE! | DK1: =AND(Syllabus!B21,"AAAAAH7b/3I=") -> #VALUE! | DL1: =AND(Syllabus!C21,"AAAAAH7b/3M=") -> #VALUE! | DM1: =AND(Syllabus!D21,"AAAAAH7b/3Q=") -> TRUE | DN1: =AND(Syllabus!E21,"AAAAAH7b/3U=") -> #VALUE! | DO1: =AND(Syllabus!F21,"AAAAAH7b/3Y=") -> #VALUE! | DP1: =AND(Syllabus!G21,"AAAAAH7b/3c=") -> #VALUE! | DQ1: =IF(Syllabus!24:24,"AAAAAH7b/3g=",0) -> 0 | DR1: =AND(Syllabus!A24,"AAAAAH7b/3k=") -> #VALUE! | DS1: =AND(Syllabus!B24,"AAAAAH7b/3o=") -> #VALUE! | DT1: =AND(Syllabus!C24,"AAAAAH7b/3s=") -> #VALUE! | DU1: =AND(Syllabus!D24,"AAAAAH7b/3w=") -> FALSE | DV1: =AND(Syllabus!E24,"AAAAAH7b/30=") -> #VALUE! | DW1: =AND(Syllabus!F24,"AAAAAH7b/34=") -> #VALUE! | DX1: =AND(Syllabus!G24,"AAAAAH7b/38=") -> #VALUE! | DY1: =IF(Syllabus!25:25,"AAAAAH7b/4A=",0) -> 0 | DZ1: =AND(Syllabus!A25,"AAAAAH7b/4E=") -> #VALUE! | EA1: =AND(Syllabus!B25,"AAAAAH7b/4I=") -> #VALUE! | EB1: =AND(Syllabus!C25,"AAAAAH7b/4M=") -> #VALUE! | EC1: =AND(Syllabus!D25,"AAAAAH7b/4Q=") -> TRUE | ED1: =AND(Syllabus!E25,"AAAAAH7b/4U=") -> #VALUE! | EE1: =AND(Syllabus!F25,"AAAAAH7b/4Y=") -> #VALUE! | EF1: =AND(Syllabus!G25,"AAAAAH7b/4c=") -> #VALUE! | EG1: =IF(Syllabus!26:26,"AAAAAH7b/4g=",0) -> 0 | EH1: =AND(Syllabus!A26,"AAAAAH7b/4k=") -> TRUE | EI1: =AND(Syllabus!B26,"AAAAAH7b/4o=") -> #VALUE! | EJ1: =AND(Syllabus!C26,"AAAAAH7b/4s=") -> #VALUE! | EK1: =AND(Syllabus!D26,"AAAAAH7b/4w=") -> #VALUE! | EL1: =AND(Syllabus!E26,"AAAAAH7b/40=") -> #VALUE! | EM1: =AND(Syllabus!F26,"AAAAAH7b/44=") -> #VALUE! | EN1: =AND(Syllabus!G26,"AAAAAH7b/48=") -> #VALUE! | EO1: =IF(Syllabus!#REF!,"AAAAAH7b/5A=",0) -> #REF! | EP1: =AND(Syllabus!#REF!,"AAAAAH7b/5E=") -> #REF! | EQ1: =AND(Syllabus!#REF!,"AAAAAH7b/5I=") -> #REF! | ER1: =AND(Syllabus!#REF!,"AAAAAH7b/5M=") -> #REF! | ES1: =AND(Syllabus!#REF!,"AAAAAH7b/5Q=") -> #REF! | ET1: =AND(Syllabus!#REF!,"AAAAAH7b/5U=") -> #REF! | EU1: =AND(Syllabus!#REF!,"AAAAAH7b/5Y=") -> #REF! | EV1: =AND(Syllabus!#REF!,"AAAAAH7b/5c=") -> #REF! | EW1: =IF(Syllabus!27:27,"AAAAAH7b/5g=",0) -> 0 | EX1: =AND(Syllabus!A27,"AAAAAH7b/5k=") -> #VALUE! | EY1: =AND(Syllabus!B27,"AAAAAH7b/5o=") -> #VALUE! | EZ1: =AND(Syllabus!C27,"AAAAAH7b/5s=") -> #VALUE! | FA1: =AND(Syllabus!D27,"AAAAAH7b/5w=") -> #VALUE! | FB1: =AND(Syllabus!E27,"AAAAAH7b/50=") -> #VALUE! | FC1: =AND(Syllabus!F27,"AAAAAH7b/54=") -> #VALUE! | FD1: =AND(Syllabus!G27,"AAAAAH7b/58=") -> #VALUE! | FE1: =IF(Syllabus!#REF!,"AAAAAH7b/6A=",0) -> #REF! | FF1: =AND(Syllabus!#REF!,"AAAAAH7b/6E=") -> #REF! | FG1: =AND(Syllabus!#REF!,"AAAAAH7b/6I=") -> #REF! | FH1: =AND(Syllabus!#REF!,"AAAAAH7b/6M=") -> #REF! | FI1: =AND(Syllabus!#REF!,"AAAAAH7b/6Q=") -> #REF! | FJ1: =AND(Syllabus!#REF!,"AAAAAH7b/6U=") -> #REF! | FK1: =AND(Syllabus!#REF!,"AAAAAH7b/6Y=") -> #REF! | FL1: =AND(Syllabus!#REF!,"AAAAAH7b/6c=") -> #REF! | FM1: =IF(Syllabus!#REF!,"AAAAAH7b/6g=",0) -> #REF! | FN1: =AND(Syllabus!#REF!,"AAAAAH7b/6k=") -> #REF! | FO1: =AND(Syllabus!#REF!,"AAAAAH7b/6o=") -> #REF! | FP1: =AND(Syllabus!#REF!,"AAAAAH7b/6s=") -> #REF! | FQ1: =AND(Syllabus!#REF!,"AAAAAH7b/6w=") -> #REF! | FR1: =AND(Syllabus!#REF!,"AAAAAH7b/60=") -> #REF! | FS1: =AND(Syllabus!#REF!,"AAAAAH7b/64=") -> #REF! | FT1: =AND(Syllabus!#REF!,"AAAAAH7b/68=") -> #REF! | FU1: =IF(Syllabus!28:28,"AAAAAH7b/7A=",0) -> 0 | FV1: =AND(Syllabus!A28,"AAAAAH7b/7E=") -> #VALUE! | FW1: =AND(Syllabus!B28,"AAAAAH7b/7I=") -> #VALUE! | FX1: =AND(Syllabus!C28,"AAAAAH7b/7M=") -> #VALUE! | FY1: =AND(Syllabus!D28,"AAAAAH7b/7Q=") -> #VALUE! | FZ1: =AND(Syllabus!E28,"AAAAAH7b/7U=") -> #VALUE! | GA1: =AND(Syllabus!F28,"AAAAAH7b/7Y=") -> #VALUE! | GB1: =AND(Syllabus!G28,"AAAAAH7b/7c=") -> #VALUE! | GC1: =IF(Syllabus!29:29,"AAAAAH7b/7g=",0) -> 0 | GD1: =AND(Syllabus!A29,"AAAAAH7b/7k=") -> TRUE | GE1: =AND(Syllabus!B29,"AAAAAH7b/7o=") -> #VALUE! | GF1: =AND(Syllabus!C29,"AAAAAH7b/7s=") -> #VALUE! | GG1: =AND(Syllabus!D29,"AAAAAH7b/7w=") -> TRUE | GH1: =AND(Syllabus!E29,"AAAAAH7b/70=") -> TRUE | GI1: =AND(Syllabus!F29,"AAAAAH7b/74=") -> #VALUE! | GJ1: =AND(Syllabus!G29,"AAAAAH7b/78=") -> #VALUE! | GK1: =IF(Syllabus!30:30,"AAAAAH7b/8A=",0) -> 0 | GL1: =AND(Syllabus!A30,"AAAAAH7b/8E=") -> #VALUE! | GM1: =AND(Syllabus!B30,"AAAAAH7b/8I=") -> #VALUE! | GN1: =AND(Syllabus!C30,"AAAAAH7b/8M=") -> #VALUE! | GO1: =AND(Syllabus!D30,"AAAAAH7b/8Q=") -> TRUE | GP1: =AND(Syllabus!E30,"AAAAAH7b/8U=") -> TRUE | GQ1: =AND(Syllabus!F30,"AAAAAH7b/8Y=") -> #VALUE! | GR1: =AND(Syllabus!G30,"AAAAAH7b/8c=") -> #VALUE! | GS1: =IF(_xlfn.SINGLE(Syllabus!#REF!),"AAAAAH7b/8g=",0) -> #REF! | GT1: =AND(Syllabus!#REF!,"AAAAAH7b/8k=") -> #REF! | GU1: =AND(Syllabus!#REF!,"AAAAAH7b/8o=") -> #REF! | GV1: =AND(Syllabus!#REF!,"AAAAAH7b/8s=") -> #REF! | GW1: =AND(Syllabus!#REF!,"AAAAAH7b/8w=") -> #REF! | GX1: =AND(Syllabus!#REF!,"AAAAAH7b/80=") -> #REF! | GY1: =AND(Syllabus!#REF!,"AAAAAH7b/84=") -> #REF! | GZ1: =AND(Syllabus!#REF!,"AAAAAH7b/88=") -> #REF! | HA1: =IF(Syllabus!31:31,"AAAAAH7b/9A=",0) -> 0 | HB1: =AND(Syllabus!A31,"AAAAAH7b/9E=") -> #VALUE! | HC1: =AND(Syllabus!B31,"AAAAAH7b/9I=") -> #VALUE! | HD1: =AND(Syllabus!C31,"AAAAAH7b/9M=") -> #VALUE! | HE1: =AND(Syllabus!D31,"AAAAAH7b/9Q=") -> TRUE | HF1: =AND(Syllabus!E31,"AAAAAH7b/9U=") -> #VALUE! | HG1: =AND(Syllabus!F31,"AAAAAH7b/9Y=") -> #VALUE! | HH1: =AND(Syllabus!G31,"AAAAAH7b/9c=") -> #VALUE! | HI1: =IF(Syllabus!32:32,"AAAAAH7b/9g=",0) -> 0 | HJ1: =AND(Syllabus!A32,"AAAAAH7b/9k=") -> TRUE | HK1: =AND(Syllabus!B32,"AAAAAH7b/9o=") -> #VALUE! | HL1: =AND(Syllabus!C32,"AAAAAH7b/9s=") -> #VALUE! | HM1: =AND(Syllabus!D32,"AAAAAH7b/9w=") -> #VALUE! | HN1: =AND(Syllabus!E32,"AAAAAH7b/90=") -> #VALUE! | HO1: =AND(Syllabus!F32,"AAAAAH7b/94=") -> #VALUE! | HP1: =AND(Syllabus!G32,"AAAAAH7b/98=") -> #VALUE! | HQ1: =IF(Syllabus!33:33,"AAAAAH7b/+A=",0) -> 0 | HR1: =AND(Syllabus!A33,"AAAAAH7b/+E=") -> #VALUE! | HS1: =AND(Syllabus!B33,"AAAAAH7b/+I=") -> #VALUE! | HT1: =AND(Syllabus!C33,"AAAAAH7b/+M=") -> #VALUE! | HU1: =AND(Syllabus!D33,"AAAAAH7b/+Q=") -> #VALUE! | HV1: =AND(Syllabus!E33,"AAAAAH7b/+U=") -> #VALUE! | HW1: =AND(Syllabus!F33,"AAAAAH7b/+Y=") -> #VALUE! | HX1: =AND(Syllabus!G33,"AAAAAH7b/+c=") -> #VALUE! | HY1: =IF(Syllabus!34:34,"AAAAAH7b/+g=",0) -> 0 | HZ1: =AND(Syllabus!A34,"AAAAAH7b/+k=") -> #VALUE! | IA1: =AND(Syllabus!B34,"AAAAAH7b/+o=") -> #VALUE! | IB1: =AND(Syllabus!C34,"AAAAAH7b/+s=") -> #VALUE! | IC1: =AND(Syllabus!D34,"AAAAAH7b/+w=") -> #VALUE! | ID1: =AND(Syllabus!E34,"AAAAAH7b/+0=") -> #VALUE! | IE1: =AND(Syllabus!F34,"AAAAAH7b/+4=") -> #VALUE! | IF1: =AND(Syllabus!G34,"AAAAAH7b/+8=") -> #VALUE! | IG1: =IF(Syllabus!35:35,"AAAAAH7b//A=",0) -> 0 | IH1: =AND(Syllabus!A35,"AAAAAH7b//E=") -> #VALUE! | II1: =AND(Syllabus!B35,"AAAAAH7b//I=") -> #VALUE! | IJ1: =AND(Syllabus!C35,"AAAAAH7b//M=") -> #VALUE! | IK1: =AND(Syllabus!D35,"AAAAAH7b//Q=") -> FALSE | IL1: =AND(Syllabus!E35,"AAAAAH7b//U=") -> #VALUE! | IM1: =AND(Syllabus!F35,"AAAAAH7b//Y=") -> #VALUE! | IN1: =AND(Syllabus!G35,"AAAAAH7b//c=") -> #VALUE! | IO1: =IF(Syllabus!36:36,"AAAAAH7b//g=",0) -> 0 | IP1: =AND(Syllabus!A36,"AAAAAH7b//k=") -> #VALUE! | IQ1: =AND(Syllabus!B36,"AAAAAH7b//o=") -> #VALUE! | IR1: =AND(Syllabus!C36,"AAAAAH7b//s=") -> #VALUE! | IS1: =AND(Syllabus!D36,"AAAAAH7b//w=") -> #VALUE! | IT1: =AND(Syllabus!E36,"AAAAAH7b//0=") -> #VALUE! | IU1: =AND(Syllabus!F36,"AAAAAH7b//4=") -> #VALUE! | IV1: =AND(Syllabus!G36,"AAAAAH7b//8=") -> #VALUE!
A2: =IF(Syllabus!37:37,"AAAAAH/vfwA=",0) -> 0 | B2: =AND(Syllabus!A37,"AAAAAH/vfwE=") -> #VALUE! | C2: =AND(Syllabus!B37,"AAAAAH/vfwI=") -> #VALUE! | D2: =AND(Syllabus!C37,"AAAAAH/vfwM=") -> #VALUE! | E2: =AND(Syllabus!D37,"AAAAAH/vfwQ=") -> #VALUE! | F2: =AND(Syllabus!E37,"AAAAAH/vfwU=") -> #VALUE! | G2: =AND(Syllabus!F37,"AAAAAH/vfwY=") -> #VALUE! | H2: =AND(Syllabus!G37,"AAAAAH/vfwc=") -> #VALUE! | I2: =IF(Syllabus!38:38,"AAAAAH/vfwg=",0) -> 0 | J2: =AND(Syllabus!A38,"AAAAAH/vfwk=") -> #VALUE! | K2: =AND(Syllabus!B38,"AAAAAH/vfwo=") -> #VALUE! | L2: =AND(Syllabus!C38,"AAAAAH/vfws=") -> #VALUE! | M2: =AND(Syllabus!D38,"AAAAAH/vfww=") -> #VALUE! | N2: =AND(Syllabus!E38,"AAAAAH/vfw0=") -> #VALUE! | O2: =AND(Syllabus!F38,"AAAAAH/vfw4=") -> #VALUE! | P2: =AND(Syllabus!G38,"AAAAAH/vfw8=") -> #VALUE! | Q2: =IF(Syllabus!#REF!,"AAAAAH/vfxA=",0) -> #REF! | R2: =IF(Syllabus!A:A,"AAAAAH/vfxE=",0) -> AAAAAH/vfxE= | S2: =IF(Syllabus!B:B,"AAAAAH/vfxI=",0) -> #VALUE! | T2: =IF(Syllabus!C:C,"AAAAAH/vfxM=",0) -> #VALUE! | U2: =IF(Syllabus!D:D,"AAAAAH/vfxQ=",0) -> 0 | V2: =IF(Syllabus!E:E,"AAAAAH/vfxU=",0) -> 0 | W2: =IF(Syllabus!F:F,"AAAAAH/vfxY=",0) -> 0 | X2: =IF(Syllabus!G:G,"AAAAAH/vfxc=",0) -> 0 | Y2: =IF(#REF!,"AAAAAH/vfxg=",0) -> #REF! | Z2: =AND(#REF!,"AAAAAH/vfxk=") -> #REF! | AA2: =AND(#REF!,"AAAAAH/vfxo=") -> #REF! | AB2: =AND(#REF!,"AAAAAH/vfxs=") -> #REF! | AC2: =AND(#REF!,"AAAAAH/vfxw=") -> #REF! | AD2: =AND(#REF!,"AAAAAH/vfx0=") -> #REF! | AE2: =AND(#REF!,"AAAAAH/vfx4=") -> #REF! | AF2: =IF(#REF!,"AAAAAH/vfx8=",0) -> #REF! | AG2: =AND(#REF!,"AAAAAH/vfyA=") -> #REF! | AH2: =AND(#REF!,"AAAAAH/vfyE=") -> #REF! | AI2: =AND(#REF!,"AAAAAH/vfyI=") -> #REF! | AJ2: =AND(#REF!,"AAAAAH/vfyM=") -> #REF! | AK2: =AND(#REF!,"AAAAAH/vfyQ=") -> #REF! | AL2: =AND(#REF!,"AAAAAH/vfyU=") -> #REF! | AM2: =IF(#REF!,"AAAAAH/vfyY=",0) -> #REF! | AN2: =AND(#REF!,"AAAAAH/vfyc=") -> #REF! | AO2: =AND(#REF!,"AAAAAH/vfyg=") -> #REF! | AP2: =AND(#REF!,"AAAAAH/vfyk=") -> #REF! | AQ2: =AND(#REF!,"AAAAAH/vfyo=") -> #REF! | AR2: =AND(#REF!,"AAAAAH/vfys=") -> #REF! | AS2: =AND(#REF!,"AAAAAH/vfyw=") -> #REF! | AT2: =IF(#REF!,"AAAAAH/vfy0=",0) -> #REF! | AU2: =AND(#REF!,"AAAAAH/vfy4=") -> #REF! | AV2: =AND(#REF!,"AAAAAH/vfy8=") -> #REF! | AW2: =AND(#REF!,"AAAAAH/vfzA=") -> #REF! | AX2: =AND(#REF!,"AAAAAH/vfzE=") -> #REF! | AY2: =AND(#REF!,"AAAAAH/vfzI=") -> #REF! | AZ2: =AND(#REF!,"AAAAAH/vfzM=") -> #REF! | BA2: =IF(#REF!,"AAAAAH/vfzQ=",0) -> #REF! | BB2: =AND(#REF!,"AAAAAH/vfzU=") -> #REF! | BC2: =AND(#REF!,"AAAAAH/vfzY=") -> #REF! | BD2: =AND(#REF!,"AAAAAH/vfzc=") -> #REF! | BE2: =AND(#REF!,"AAAAAH/vfzg=") -> #REF! | BF2: =AND(#REF!,"AAAAAH/vfzk=") -> #REF! | BG2: =AND(#REF!,"AAAAAH/vfzo=") -> #REF! | BH2: =IF(#REF!,"AAAAAH/vfzs=",0) -> #REF! | BI2: =AND(#REF!,"AAAAAH/vfzw=") -> #REF! | BJ2: =AND(#REF!,"AAAAAH/vfz0=") -> #REF! | BK2: =AND(#REF!,"AAAAAH/vfz4=") -> #REF! | BL2: =AND(#REF!,"AAAAAH/vfz8=") -> #REF! | BM2: =AND(#REF!,"AAAAAH/vf0A=") -> #REF! | BN2: =AND(#REF!,"AAAAAH/vf0E=") -> #REF! | BO2: =IF(#REF!,"AAAAAH/vf0I=",0) -> #REF! | BP2: =AND(#REF!,"AAAAAH/vf0M=") -> #REF! | BQ2: =AND(#REF!,"AAAAAH/vf0Q=") -> #REF! | BR2: =AND(#REF!,"AAAAAH/vf0U=") -> #REF! | BS2: =AND(#REF!,"AAAAAH/vf0Y=") -> #REF! | BT2: =AND(#REF!,"AAAAAH/vf0c=") -> #REF! | BU2: =AND(#REF!,"AAAAAH/vf0g=") -> #REF! | BV2: =IF(#REF!,"AAAAAH/vf0k=",0) -> #REF! | BW2: =AND(#REF!,"AAAAAH/vf0o=") -> #REF! | BX2: =AND(#REF!,"AAAAAH/vf0s=") -> #REF! | BY2: =AND(#REF!,"AAAAAH/vf0w=") -> #REF! | BZ2: =AND(#REF!,"AAAAAH/vf00=") -> #REF! | CA2: =AND(#REF!,"AAAAAH/vf04=") -> #REF! | CB2: =AND(#REF!,"AAAAAH/vf08=") -> #REF! | CC2: =IF(#REF!,"AAAAAH/vf1A=",0) -> #REF! | CD2: =AND(#REF!,"AAAAAH/vf1E=") -> #REF! | CE2: =AND(#REF!,"AAAAAH/vf1I=") -> #REF! | CF2: =AND(#REF!,"AAAAAH/vf1M=") -> #REF! | CG2: =AND(#REF!,"AAAAAH/vf1Q=") -> #REF! | CH2: =AND(#REF!,"AAAAAH/vf1U=") -> #REF! | CI2: =AND(#REF!,"AAAAAH/vf1Y=") -> #REF! | CJ2: =IF(#REF!,"AAAAAH/vf1c=",0) -> #REF! | CK2: =AND(#REF!,"AAAAAH/vf1g=") -> #REF! | CL2: =AND(#REF!,"AAAAAH/vf1k=") -> #REF! | CM2: =AND(#REF!,"AAAAAH/vf1o=") -> #REF! | CN2: =AND(#REF!,"AAAAAH/vf1s=") -> #REF! | CO2: =AND(#REF!,"AAAAAH/vf1w=") -> #REF! | CP2: =AND(#REF!,"AAAAAH/vf10=") -> #REF! | CQ2: =IF(#REF!,"AAAAAH/vf14=",0) -> #REF! | CR2: =AND(#REF!,"AAAAAH/vf18=") -> #REF! | CS2: =AND(#REF!,"AAAAAH/vf2A=") -> #REF! | CT2: =AND(#REF!,"AAAAAH/vf2E=") -> #REF! | CU2: =AND(#REF!,"AAAAAH/vf2I=") -> #REF! | CV2: =AND(#REF!,"AAAAAH/vf2M=") -> #REF! | CW2: =AND(#REF!,"AAAAAH/vf2Q=") -> #REF! | CX2: =IF(#REF!,"AAAAAH/vf2U=",0) -> #REF! | CY2: =AND(#REF!,"AAAAAH/vf2Y=") -> #REF! | CZ2: =AND(#REF!,"AAAAAH/vf2c=") -> #REF! | DA2: =AND(#REF!,"AAAAAH/vf2g=") -> #REF! | DB2: =AND(#REF!,"AAAAAH/vf2k=") -> #REF! | DC2: =AND(#REF!,"AAAAAH/vf2o=") -> #REF! | DD2: =AND(#REF!,"AAAAAH/vf2s=") -> #REF! | DE2: =IF(#REF!,"AAAAAH/vf2w=",0) -> #REF! | DF2: =AND(#REF!,"AAAAAH/vf20=") -> #REF! | DG2: =AND(#REF!,"AAAAAH/vf24=") -> #REF! | DH2: =AND(#REF!,"AAAAAH/vf28=") -> #REF! | DI2: =AND(#REF!,"AAAAAH/vf3A=") -> #REF! | DJ2: =AND(#REF!,"AAAAAH/vf3E=") -> #REF! | DK2: =AND(#REF!,"AAAAAH/vf3I=") -> #REF! | DL2: =IF(#REF!,"AAAAAH/vf3M=",0) -> #REF! | DM2: =AND(#REF!,"AAAAAH/vf3Q=") -> #REF! | DN2: =AND(#REF!,"AAAAAH/vf3U=") -> #REF! | DO2: =AND(#REF!,"AAAAAH/vf3Y=") -> #REF! | DP2: =AND(#REF!,"AAAAAH/vf3c=") -> #REF! | DQ2: =AND(#REF!,"AAAAAH/vf3g=") -> #REF! | DR2: =AND(#REF!,"AAAAAH/vf3k=") -> #REF! | DS2: =IF(#REF!,"AAAAAH/vf3o=",0) -> #REF! | DT2: =AND(#REF!,"AAAAAH/vf3s=") -> #REF! | DU2: =AND(#REF!,"AAAAAH/vf3w=") -> #REF! | DV2: =AND(#REF!,"AAAAAH/vf30=") -> #REF! | DW2: =AND(#REF!,"AAAAAH/vf34=") -> #REF! | DX2: =AND(#REF!,"AAAAAH/vf38=") -> #REF! | DY2: =AND(#REF!,"AAAAAH/vf4A=") -> #REF! | DZ2: =IF(#REF!,"AAAAAH/vf4E=",0) -> #REF! | EA2: =AND(#REF!,"AAAAAH/vf4I=") -> #REF! | EB2: =AND(#REF!,"AAAAAH/vf4M=") -> #REF! | EC2: =AND(#REF!,"AAAAAH/vf4Q=") -> #REF! | ED2: =AND(#REF!,"AAAAAH/vf4U=") -> #REF! | EE2: =AND(#REF!,"AAAAAH/vf4Y=") -> #REF! | EF2: =AND(#REF!,"AAAAAH/vf4c=") -> #REF! | EG2: =IF(#REF!,"AAAAAH/vf4g=",0) -> #REF! | EH2: =AND(#REF!,"AAAAAH/vf4k=") -> #REF! | EI2: =AND(#REF!,"AAAAAH/vf4o=") -> #REF! | EJ2: =AND(#REF!,"AAAAAH/vf4s=") -> #REF! | EK2: =AND(#REF!,"AAAAAH/vf4w=") -> #REF! | EL2: =AND(#REF!,"AAAAAH/vf40=") -> #REF! | EM2: =AND(#REF!,"AAAAAH/vf44=") -> #REF! | EN2: =IF(#REF!,"AAAAAH/vf48=",0) -> #REF! | EO2: =AND(#REF!,"AAAAAH/vf5A=") -> #REF! | EP2: =AND(#REF!,"AAAAAH/vf5E=") -> #REF! | EQ2: =AND(#REF!,"AAAAAH/vf5I=") -> #REF! | ER2: =AND(#REF!,"AAAAAH/vf5M=") -> #REF! | ES2: =AND(#REF!,"AAAAAH/vf5Q=") -> #REF! | ET2: =AND(#REF!,"AAAAAH/vf5U=") -> #REF! | EU2: =IF(#REF!,"AAAAAH/vf5Y=",0) -> #REF! | EV2: =AND(#REF!,"AAAAAH/vf5c=") -> #REF! | EW2: =AND(#REF!,"AAAAAH/vf5g=") -> #REF! | EX2: =AND(#REF!,"AAAAAH/vf5k=") -> #REF! | EY2: =AND(#REF!,"AAAAAH/vf5o=") -> #REF! | EZ2: =AND(#REF!,"AAAAAH/vf5s=") -> #REF! | FA2: =AND(#REF!,"AAAAAH/vf5w=") -> #REF! | FB2: =IF(#REF!,"AAAAAH/vf50=",0) -> #REF! | FC2: =AND(#REF!,"AAAAAH/vf54=") -> #REF! | FD2: =AND(#REF!,"AAAAAH/vf58=") -> #REF! | FE2: =AND(#REF!,"AAAAAH/vf6A=") -> #REF! | FF2: =AND(#REF!,"AAAAAH/vf6E=") -> #REF! | FG2: =AND(#REF!,"AAAAAH/vf6I=") -> #REF! | FH2: =AND(#REF!,"AAAAAH/vf6M=") -> #REF! | FI2: =IF(#REF!,"AAAAAH/vf6Q=",0) -> #REF! | FJ2: =AND(#REF!,"AAAAAH/vf6U=") -> #REF! | FK2: =AND(#REF!,"AAAAAH/vf6Y=") -> #REF! | FL2: =AND(#REF!,"AAAAAH/vf6c=") -> #REF! | FM2: =AND(#REF!,"AAAAAH/vf6g=") -> #REF! | FN2: =AND(#REF!,"AAAAAH/vf6k=") -> #REF! | FO2: =AND(#REF!,"AAAAAH/vf6o=") -> #REF! | FP2: =IF(#REF!,"AAAAAH/vf6s=",0) -> #REF! | FQ2: =AND(#REF!,"AAAAAH/vf6w=") -> #REF! | FR2: =AND(#REF!,"AAAAAH/vf60=") -> #REF! | FS2: =AND(#REF!,"AAAAAH/vf64=") -> #REF! | FT2: =AND(#REF!,"AAAAAH/vf68=") -> #REF! | FU2: =AND(#REF!,"AAAAAH/vf7A=") -> #REF! | FV2: =AND(#REF!,"AAAAAH/vf7E=") -> #REF! | FW2: =IF(#REF!,"AAAAAH/vf7I=",0) -> #REF! | FX2: =AND(#REF!,"AAAAAH/vf7M=") -> #REF! | FY2: =AND(#REF!,"AAAAAH/vf7Q=") -> #REF! | FZ2: =AND(#REF!,"AAAAAH/vf7U=") -> #REF! | GA2: =AND(#REF!,"AAAAAH/vf7Y=") -> #REF! | GB2: =AND(#REF!,"AAAAAH/vf7c=") -> #REF! | GC2: =AND(#REF!,"AAAAAH/vf7g=") -> #REF! | GD2: =IF(#REF!,"AAAAAH/vf7k=",0) -> #REF! | GE2: =AND(#REF!,"AAAAAH/vf7o=") -> #REF! | GF2: =AND(#REF!,"AAAAAH/vf7s=") -> #REF! | GG2: =AND(#REF!,"AAAAAH/vf7w=") -> #REF! | GH2: =AND(#REF!,"AAAAAH/vf70=") -> #REF! | GI2: =AND(#REF!,"AAAAAH/vf74=") -> #REF! | GJ2: =AND(#REF!,"AAAAAH/vf78=") -> #REF! | GK2: =IF(#REF!,"AAAAAH/vf8A=",0) -> #REF! | GL2: =AND(#REF!,"AAAAAH/vf8E=") -> #REF! | GM2: =AND(#REF!,"AAAAAH/vf8I=") -> #REF! | GN2: =AND(#REF!,"AAAAAH/vf8M=") -> #REF! | GO2: =AND(#REF!,"AAAAAH/vf8Q=") -> #REF! | GP2: =AND(#REF!,"AAAAAH/vf8U=") -> #REF! | GQ2: =AND(#REF!,"AAAAAH/vf8Y=") -> #REF! | GR2: =IF(#REF!,"AAAAAH/vf8c=",0) -> #REF! | GS2: =AND(#REF!,"AAAAAH/vf8g=") -> #REF! | GT2: =AND(#REF!,"AAAAAH/vf8k=") -> #REF! | GU2: =AND(#REF!,"AAAAAH/vf8o=") -> #REF! | GV2: =AND(#REF!,"AAAAAH/vf8s=") -> #REF! | GW2: =AND(#REF!,"AAAAAH/vf8w=") -> #REF! | GX2: =AND(#REF!,"AAAAAH/vf80=") -> #REF! | GY2: =IF(#REF!,"AAAAAH/vf84=",0) -> #REF! | GZ2: =AND(#REF!,"AAAAAH/vf88=") -> #REF! | HA2: =AND(#REF!,"AAAAAH/vf9A=") -> #REF! | HB2: =AND(#REF!,"AAAAAH/vf9E=") -> #REF! | HC2: =AND(#REF!,"AAAAAH/vf9I=") -> #REF! | HD2: =AND(#REF!,"AAAAAH/vf9M=") -> #REF! | HE2: =AND(#REF!,"AAAAAH/vf9Q=") -> #REF! | HF2: =IF(#REF!,"AAAAAH/vf9U=",0) -> #REF! | HG2: =AND(#REF!,"AAAAAH/vf9Y=") -> #REF! | HH2: =AND(#REF!,"AAAAAH/vf9c=") -> #REF! | HI2: =AND(#REF!,"AAAAAH/vf9g=") -> #REF! | HJ2: =AND(#REF!,"AAAAAH/vf9k=") -> #REF! | HK2: =AND(#REF!,"AAAAAH/vf9o=") -> #REF! | HL2: =AND(#REF!,"AAAAAH/vf9s=") -> #REF! | HM2: =IF(#REF!,"AAAAAH/vf9w=",0) -> #REF! | HN2: =AND(#REF!,"AAAAAH/vf90=") -> #REF! | HO2: =AND(#REF!,"AAAAAH/vf94=") -> #REF! | HP2: =AND(#REF!,"AAAAAH/vf98=") -> #REF! | HQ2: =AND(#REF!,"AAAAAH/vf+A=") -> #REF! | HR2: =AND(#REF!,"AAAAAH/vf+E=") -> #REF! | HS2: =AND(#REF!,"AAAAAH/vf+I=") -> #REF! | HT2: =IF(#REF!,"AAAAAH/vf+M=",0) -> #REF! | HU2: =AND(#REF!,"AAAAAH/vf+Q=") -> #REF! | HV2: =AND(#REF!,"AAAAAH/vf+U=") -> #REF! | HW2: =AND(#REF!,"AAAAAH/vf+Y=") -> #REF! | HX2: =AND(#REF!,"AAAAAH/vf+c=") -> #REF! | HY2: =AND(#REF!,"AAAAAH/vf+g=") -> #REF! | HZ2: =AND(#REF!,"AAAAAH/vf+k=") -> #REF! | IA2: =IF(#REF!,"AAAAAH/vf+o=",0) -> #REF! | IB2: =AND(#REF!,"AAAAAH/vf+s=") -> #REF! | IC2: =AND(#REF!,"AAAAAH/vf+w=") -> #REF! | ID2: =AND(#REF!,"AAAAAH/vf+0=") -> #REF! | IE2: =AND(#REF!,"AAAAAH/vf+4=") -> #REF! | IF2: =AND(#REF!,"AAAAAH/vf+8=") -> #REF! | IG2: =AND(#REF!,"AAAAAH/vf/A=") -> #REF! | IH2: =IF(#REF!,"AAAAAH/vf/E=",0) -> #REF! | II2: =AND(#REF!,"AAAAAH/vf/I=") -> #REF! | IJ2: =AND(#REF!,"AAAAAH/vf/M=") -> #REF! | IK2: =AND(#REF!,"AAAAAH/vf/Q=") -> #REF! | IL2: =AND(#REF!,"AAAAAH/vf/U=") -> #REF! | IM2: =AND(#REF!,"AAAAAH/vf/Y=") -> #REF! | IN2: =AND(#REF!,"AAAAAH/vf/c=") -> #REF! | IO2: =IF(#REF!,"AAAAAH/vf/g=",0) -> #REF! | IP2: =AND(#REF!,"AAAAAH/vf/k=") -> #REF! | IQ2: =AND(#REF!,"AAAAAH/vf/o=") -> #REF! | IR2: =AND(#REF!,"AAAAAH/vf/s=") -> #REF! | IS2: =AND(#REF!,"AAAAAH/vf/w=") -> #REF! | IT2: =AND(#REF!,"AAAAAH/vf/0=") -> #REF! | IU2: =AND(#REF!,"AAAAAH/vf/4=") -> #REF! | IV2: =IF(#REF!,"AAAAAH/vf/8=",0) -> #REF!
A3: =AND(#REF!,"AAAAABPz/wA=") -> #REF! | B3: =AND(#REF!,"AAAAABPz/wE=") -> #REF! | C3: =AND(#REF!,"AAAAABPz/wI=") -> #REF! | D3: =AND(#REF!,"AAAAABPz/wM=") -> #REF! | E3: =AND(#REF!,"AAAAABPz/wQ=") -> #REF! | F3: =AND(#REF!,"AAAAABPz/wU=") -> #REF! | G3: =IF(#REF!,"AAAAABPz/wY=",0) -> #REF! | H3: =AND(#REF!,"AAAAABPz/wc=") -> #REF! | I3: =AND(#REF!,"AAAAABPz/wg=") -> #REF! | J3: =AND(#REF!,"AAAAABPz/wk=") -> #REF! | K3: =AND(#REF!,"AAAAABPz/wo=") -> #REF! | L3: =AND(#REF!,"AAAAABPz/ws=") -> #REF! | M3: =AND(#REF!,"AAAAABPz/ww=") -> #REF! | N3: =IF(#REF!,"AAAAABPz/w0=",0) -> #REF! | O3: =AND(#REF!,"AAAAABPz/w4=") -> #REF! | P3: =AND(#REF!,"AAAAABPz/w8=") -> #REF! | Q3: =AND(#REF!,"AAAAABPz/xA=") -> #REF! | R3: =AND(#REF!,"AAAAABPz/xE=") -> #REF! | S3: =AND(#REF!,"AAAAABPz/xI=") -> #REF! | T3: =AND(#REF!,"AAAAABPz/xM=") -> #REF! | U3: =IF(#REF!,"AAAAABPz/xQ=",0) -> #REF! | V3: =AND(#REF!,"AAAAABPz/xU=") -> #REF! | W3: =AND(#REF!,"AAAAABPz/xY=") -> #REF! | X3: =AND(#REF!,"AAAAABPz/xc=") -> #REF! | Y3: =AND(#REF!,"AAAAABPz/xg=") -> #REF! | Z3: =AND(#REF!,"AAAAABPz/xk=") -> #REF! | AA3: =AND(#REF!,"AAAAABPz/xo=") -> #REF! | AB3: =IF(#REF!,"AAAAABPz/xs=",0) -> #REF! | AC3: =AND(#REF!,"AAAAABPz/xw=") -> #REF! | AD3: =AND(#REF!,"AAAAABPz/x0=") -> #REF! | AE3: =AND(#REF!,"AAAAABPz/x4=") -> #REF! | AF3: =AND(#REF!,"AAAAABPz/x8=") -> #REF! | AG3: =AND(#REF!,"AAAAABPz/yA=") -> #REF! | AH3: =AND(#REF!,"AAAAABPz/yE=") -> #REF! | AI3: =IF(#REF!,"AAAAABPz/yI=",0) -> #REF! | AJ3: =AND(#REF!,"AAAAABPz/yM=") -> #REF! | AK3: =AND(#REF!,"AAAAABPz/yQ=") -> #REF! | AL3: =AND(#REF!,"AAAAABPz/yU=") -> #REF! | AM3: =AND(#REF!,"AAAAABPz/yY=") -> #REF! | AN3: =AND(#REF!,"AAAAABPz/yc=") -> #REF! | AO3: =AND(#REF!,"AAAAABPz/yg=") -> #REF! | AP3: =IF(#REF!,"AAAAABPz/yk=",0) -> #REF! | AQ3: =AND(#REF!,"AAAAABPz/yo=") -> #REF! | AR3: =AND(#REF!,"AAAAABPz/ys=") -> #REF! | AS3: =AND(#REF!,"AAAAABPz/yw=") -> #REF! | AT3: =AND(#REF!,"AAAAABPz/y0=") -> #REF! | AU3: =AND(#REF!,"AAAAABPz/y4=") -> #REF! | AV3: =AND(#REF!,"AAAAABPz/y8=") -> #REF! | AW3: =IF(#REF!,"AAAAABPz/zA=",0) -> #REF! | AX3: =AND(#REF!,"AAAAABPz/zE=") -> #REF! | AY3: =AND(#REF!,"AAAAABPz/zI=") -> #REF! | AZ3: =AND(#REF!,"AAAAABPz/zM=") -> #REF! | BA3: =AND(#REF!,"AAAAABPz/zQ=") -> #REF! | BB3: =AND(#REF!,"AAAAABPz/zU=") -> #REF! | BC3: =AND(#REF!,"AAAAABPz/zY=") -> #REF! | BD3: =IF(#REF!,"AAAAABPz/zc=",0) -> #REF! | BE3: =AND(#REF!,"AAAAABPz/zg=") -> #REF! | BF3: =AND(#REF!,"AAAAABPz/zk=") -> #REF! | BG3: =AND(#REF!,"AAAAABPz/zo=") -> #REF! | BH3: =AND(#REF!,"AAAAABPz/zs=") -> #REF! | BI3: =AND(#REF!,"AAAAABPz/zw=") -> #REF! | BJ3: =AND(#REF!,"AAAAABPz/z0=") -> #REF! | BK3: =IF(#REF!,"AAAAABPz/z4=",0) -> #REF! | BL3: =AND(#REF!,"AAAAABPz/z8=") -> #REF! | BM3: =AND(#REF!,"AAAAABPz/0A=") -> #REF! | BN3: =AND(#REF!,"AAAAABPz/0E=") -> #REF! | BO3: =AND(#REF!,"AAAAABPz/0I=") -> #REF! | BP3: =AND(#REF!,"AAAAABPz/0M=") -> #REF! | BQ3: =AND(#REF!,"AAAAABPz/0Q=") -> #REF! | BR3: =IF(#REF!,"AAAAABPz/0U=",0) -> #REF! | BS3: =AND(#REF!,"AAAAABPz/0Y=") -> #REF! | BT3: =AND(#REF!,"AAAAABPz/0c=") -> #REF! | BU3: =AND(#REF!,"AAAAABPz/0g=") -> #REF! | BV3: =AND(#REF!,"AAAAABPz/0k=") -> #REF! | BW3: =AND(#REF!,"AAAAABPz/0o=") -> #REF! | BX3: =AND(#REF!,"AAAAABPz/0s=") -> #REF! | BY3: =IF(#REF!,"AAAAABPz/0w=",0) -> #REF! | BZ3: =AND(#REF!,"AAAAABPz/00=") -> #REF! | CA3: =AND(#REF!,"AAAAABPz/04=") -> #REF! | CB3: =AND(#REF!,"AAAAABPz/08=") -> #REF! | CC3: =AND(#REF!,"AAAAABPz/1A=") -> #REF! | CD3: =AND(#REF!,"AAAAABPz/1E=") -> #REF! | CE3: =AND(#REF!,"AAAAABPz/1I=") -> #REF! | CF3: =IF(#REF!,"AAAAABPz/1M=",0) -> #REF! | CG3: =AND(#REF!,"AAAAABPz/1Q=") -> #REF! | CH3: =AND(#REF!,"AAAAABPz/1U=") -> #REF! | CI3: =AND(#REF!,"AAAAABPz/1Y=") -> #REF! | CJ3: =AND(#REF!,"AAAAABPz/1c=") -> #REF! | CK3: =AND(#REF!,"AAAAABPz/1g=") -> #REF! | CL3: =AND(#REF!,"AAAAABPz/1k=") -> #REF! | CM3: =IF(#REF!,"AAAAABPz/1o=",0) -> #REF! | CN3: =AND(#REF!,"AAAAABPz/1s=") -> #REF! | CO3: =AND(#REF!,"AAAAABPz/1w=") -> #REF! | CP3: =AND(#REF!,"AAAAABPz/10=") -> #REF! | CQ3: =AND(#REF!,"AAAAABPz/14=") -> #REF! | CR3: =AND(#REF!,"AAAAABPz/18=") -> #REF! | CS3: =AND(#REF!,"AAAAABPz/2A=") -> #REF! | CT3: =IF(#REF!,"AAAAABPz/2E=",0) -> #REF! | CU3: =AND(#REF!,"AAAAABPz/2I=") -> #REF! | CV3: =AND(#REF!,"AAAAABPz/2M=") -> #REF! | CW3: =AND(#REF!,"AAAAABPz/2Q=") -> #REF! | CX3: =AND(#REF!,"AAAAABPz/2U=") -> #REF! | CY3: =AND(#REF!,"AAAAABPz/2Y=") -> #REF! | CZ3: =AND(#REF!,"AAAAABPz/2c=") -> #REF! | DA3: =IF(#REF!,"AAAAABPz/2g=",0) -> #REF! | DB3: =AND(#REF!,"AAAAABPz/2k=") -> #REF! | DC3: =AND(#REF!,"AAAAABPz/2o=") -> #REF! | DD3: =AND(#REF!,"AAAAABPz/2s=") -> #REF! | DE3: =AND(#REF!,"AAAAABPz/2w=") -> #REF! | DF3: =AND(#REF!,"AAAAABPz/20=") -> #REF! | DG3: =AND(#REF!,"AAAAABPz/24=") -> #REF! | DH3: =IF(#REF!,"AAAAABPz/28=",0) -> #REF! | DI3: =AND(#REF!,"AAAAABPz/3A=") -> #REF! | DJ3: =AND(#REF!,"AAAAABPz/3E=") -> #REF! | DK3: =AND(#REF!,"AAAAABPz/3I=") -> #REF! | DL3: =AND(#REF!,"AAAAABPz/3M=") -> #REF! | DM3: =AND(#REF!,"AAAAABPz/3Q=") -> #REF! | DN3: =AND(#REF!,"AAAAABPz/3U=") -> #REF! | DO3: =IF(#REF!,"AAAAABPz/3Y=",0) -> #REF! | DP3: =AND(#REF!,"AAAAABPz/3c=") -> #REF! | DQ3: =AND(#REF!,"AAAAABPz/3g=") -> #REF! | DR3: =AND(#REF!,"AAAAABPz/3k=") -> #REF! | DS3: =AND(#REF!,"AAAAABPz/3o=") -> #REF! | DT3: =AND(#REF!,"AAAAABPz/3s=") -> #REF! | DU3: =IF(#REF!,"AAAAABPz/3w=",0) -> #REF! | DV3: =IF(#REF!,"AAAAABPz/30=",0) -> #REF! | DW3: =IF(#REF!,"AAAAABPz/34=",0) -> #REF! | DX3: =IF(#REF!,"AAAAABPz/38=",0) -> #REF! | DY3: =IF(#REF!,"AAAAABPz/4A=",0) -> #REF! | DZ3: =IF(#REF!,"AAAAABPz/4E=",0) -> #REF! | EA3: =IF(#REF!,"AAAAABPz/4I=",0) -> #REF! | EB3: =IF('Author and Rec of Changes'!1:1,"AAAAABPz/4M=",0) -> 0 | EC3: =AND('Author and Rec of Changes'!A1,"AAAAABPz/4Q=") -> #VALUE! | ED3: =AND('Author and Rec of Changes'!B1,"AAAAABPz/4U=") -> #VALUE! | EE3: =AND('Author and Rec of Changes'!C1,"AAAAABPz/4Y=") -> #VALUE! | EF3: =AND('Author and Rec of Changes'!E1,"AAAAABPz/4c=") -> #VALUE! | EG3: =AND('Author and Rec of Changes'!F1,"AAAAABPz/4g=") -> #VALUE! | EH3: =AND('Author and Rec of Changes'!#REF!,"AAAAABPz/4k=") -> #REF! | EI3: =IF('Author and Rec of Changes'!#REF!,"AAAAABPz/4o=",0) -> #REF! | EJ3: =AND('Author and Rec of Changes'!#REF!,"AAAAABPz/4s=") -> #REF! | EK3: =AND('Author and Rec of Changes'!#REF!,"AAAAABPz/4w=") -> #REF! | EL3: =AND('Author and Rec of Changes'!#REF!,"AAAAABPz/40=") -> #REF! | EM3: =AND('Author and Rec of Changes'!#REF!,"AAAAABPz/44=") -> #REF! | EN3: =AND('Author and Rec of Changes'!#REF!,"AAAAABPz/48=") -> #REF! | EO3: =AND('Author and Rec of Changes'!#REF!,"AAAAABPz/5A=") -> #REF! | EP3: =IF('Author and Rec of Changes'!2:2,"AAAAABPz/5E=",0) -> 0 | EQ3: =AND('Author and Rec of Changes'!A2,"AAAAABPz/5I=") -> #VALUE! | ER3: =AND('Author and Rec of Changes'!B2,"AAAAABPz/5M=") -> #VALUE! | ES3: =AND('Author and Rec of Changes'!C2,"AAAAABPz/5Q=") -> #VALUE! | ET3: =AND('Author and Rec of Changes'!E2,"AAAAABPz/5U=") -> #VALUE! | EU3: =AND('Author and Rec of Changes'!F2,"AAAAABPz/5Y=") -> #VALUE! | EV3: =AND('Author and Rec of Changes'!#REF!,"AAAAABPz/5c=") -> #REF! | EW3: =IF('Author and Rec of Changes'!3:3,"AAAAABPz/5g=",0) -> 0 | EX3: =AND('Author and Rec of Changes'!A3,"AAAAABPz/5k=") -> #VALUE! | EY3: =AND('Author and Rec of Changes'!B3,"AAAAABPz/5o=") -> #VALUE! | EZ3: =AND('Author and Rec of Changes'!C3,"AAAAABPz/5s=") -> #VALUE! | FA3: =AND('Author and Rec of Changes'!E3,"AAAAABPz/5w=") -> #VALUE! | FB3: =AND('Author and Rec of Changes'!F3,"AAAAABPz/50=") -> #VALUE! | FC3: =AND('Author and Rec of Changes'!#REF!,"AAAAABPz/54=") -> #REF! | FD3: =IF('Author and Rec of Changes'!#REF!,"AAAAABPz/58=",0) -> #REF! | FE3: =AND('Author and Rec of Changes'!#REF!,"AAAAABPz/6A=") -> #REF! | FF3: =AND('Author and Rec of Changes'!#REF!,"AAAAABPz/6E=") -> #REF! | FG3: =AND('Author and Rec of Changes'!#REF!,"AAAAABPz/6I=") -> #REF! | FH3: =AND('Author and Rec of Changes'!#REF!,"AAAAABPz/6M=") -> #REF! | FI3: =AND('Author and Rec of Changes'!#REF!,"AAAAABPz/6Q=") -> #REF! | FJ3: =AND('Author and Rec of Changes'!#REF!,"AAAAABPz/6U=") -> #REF! | FK3: =IF('Author and Rec of Changes'!#REF!,"AAAAABPz/6Y=",0) -> #REF! | FL3: =AND('Author and Rec of Changes'!#REF!,"AAAAABPz/6c=") -> #REF! | FM3: =AND('Author and Rec of Changes'!#REF!,"AAAAABPz/6g=") -> #REF! | FN3: =AND('Author and Rec of Changes'!#REF!,"AAAAABPz/6k=") -> #REF! | FO3: =AND('Author and Rec of Changes'!#REF!,"AAAAABPz/6o=") -> #REF! | FP3: =AND('Author and Rec of Changes'!#REF!,"AAAAABPz/6s=") -> #REF! | FQ3: =AND('Author and Rec of Changes'!#REF!,"AAAAABPz/6w=") -> #REF! | FR3: =IF('Author and Rec of Changes'!4:4,"AAAAABPz/60=",0) -> 0 | FS3: =AND('Author and Rec of Changes'!A4,"AAAAABPz/64=") -> #VALUE! | FT3: =AND('Author and Rec of Changes'!B4,"AAAAABPz/68=") -> #VALUE! | FU3: =AND('Author and Rec of Changes'!C4,"AAAAABPz/7A=") -> #VALUE! | FV3: =AND('Author and Rec of Changes'!E4,"AAAAABPz/7E=") -> #VALUE! | FW3: =AND('Author and Rec of Changes'!F4,"AAAAABPz/7I=") -> #VALUE! | FX3: =AND('Author and Rec of Changes'!#REF!,"AAAAABPz/7M=") -> #REF! | FY3: =IF('Author and Rec of Changes'!#REF!,"AAAAABPz/7Q=",0) -> #REF! | FZ3: =AND('Author and Rec of Changes'!#REF!,"AAAAABPz/7U=") -> #REF! | GA3: =AND('Author and Rec of Changes'!#REF!,"AAAAABPz/7Y=") -> #REF! | GB3: =AND('Author and Rec of Changes'!#REF!,"AAAAABPz/7c=") -> #REF! | GC3: =AND('Author and Rec of Changes'!#REF!,"AAAAABPz/7g=") -> #REF! | GD3: =AND('Author and Rec of Changes'!#REF!,"AAAAABPz/7k=") -> #REF! | GE3: =AND('Author and Rec of Changes'!#REF!,"AAAAABPz/7o=") -> #REF! | GF3: =IF('Author and Rec of Changes'!#REF!,"AAAAABPz/7s=",0) -> #REF! | GG3: =AND('Author and Rec of Changes'!#REF!,"AAAAABPz/7w=") -> #REF! | GH3: =AND('Author and Rec of Changes'!#REF!,"AAAAABPz/70=") -> #REF! | GI3: =AND('Author and Rec of Changes'!#REF!,"AAAAABPz/74=") -> #REF! | GJ3: =AND('Author and Rec of Changes'!#REF!,"AAAAABPz/78=") -> #REF! | GK3: =AND('Author and Rec of Changes'!#REF!,"AAAAABPz/8A=") -> #REF! | GL3: =AND('Author and Rec of Changes'!#REF!,"AAAAABPz/8E=") -> #REF! | GM3: =IF('Author and Rec of Changes'!#REF!,"AAAAABPz/8I=",0) -> #REF! | GN3: =AND('Author and Rec of Changes'!#REF!,"AAAAABPz/8M=") -> #REF! | GO3: =AND('Author and Rec of Changes'!#REF!,"AAAAABPz/8Q=") -> #REF! | GP3: =AND('Author and Rec of Changes'!#REF!,"AAAAABPz/8U=") -> #REF! | GQ3: =AND('Author and Rec of Changes'!#REF!,"AAAAABPz/8Y=") -> #REF! | GR3: =AND('Author and Rec of Changes'!#REF!,"AAAAABPz/8c=") -> #REF! | GS3: =AND('Author and Rec of Changes'!#REF!,"AAAAABPz/8g=") -> #REF! | GT3: =IF('Author and Rec of Changes'!#REF!,"AAAAABPz/8k=",0) -> #REF! | GU3: =AND('Author and Rec of Changes'!#REF!,"AAAAABPz/8o=") -> #REF! | GV3: =AND('Author and Rec of Changes'!#REF!,"AAAAABPz/8s=") -> #REF! | GW3: =AND('Author and Rec of Changes'!#REF!,"AAAAABPz/8w=") -> #REF! | GX3: =AND('Author and Rec of Changes'!#REF!,"AAAAABPz/80=") -> #REF! | GY3: =AND('Author and Rec of Changes'!#REF!,"AAAAABPz/84=") -> #REF! | GZ3: =AND('Author and Rec of Changes'!#REF!,"AAAAABPz/88=") -> #REF! | HA3: =IF('Author and Rec of Changes'!#REF!,"AAAAABPz/9A=",0) -> #REF! | HB3: =AND('Author and Rec of Changes'!#REF!,"AAAAABPz/9E=") -> #REF! | HC3: =AND('Author and Rec of Changes'!#REF!,"AAAAABPz/9I=") -> #REF! | HD3: =AND('Author and Rec of Changes'!#REF!,"AAAAABPz/9M=") -> #REF! | HE3: =AND('Author and Rec of Changes'!#REF!,"AAAAABPz/9Q=") -> #REF! | HF3: =AND('Author and Rec of Changes'!#REF!,"AAAAABPz/9U=") -> #REF! | HG3: =AND('Author and Rec of Changes'!#REF!,"AAAAABPz/9Y=") -> #REF! | HH3: =IF('Author and Rec of Changes'!#REF!,"AAAAABPz/9c=",0) -> #REF! | HI3: =AND('Author and Rec of Changes'!#REF!,"AAAAABPz/9g=") -> #REF! | HJ3: =AND('Author and Rec of Changes'!#REF!,"AAAAABPz/9k=") -> #REF! | HK3: =AND('Author and Rec of Changes'!#REF!,"AAAAABPz/9o=") -> #REF! | HL3: =AND('Author and Rec of Changes'!#REF!,"AAAAABPz/9s=") -> #REF! | HM3: =AND('Author and Rec of Changes'!#REF!,"AAAAABPz/9w=") -> #REF! | HN3: =AND('Author and Rec of Changes'!#REF!,"AAAAABPz/90=") -> #REF! | HO3: =IF('Author and Rec of Changes'!#REF!,"AAAAABPz/94=",0) -> #REF! | HP3: =AND('Author and Rec of Changes'!#REF!,"AAAAABPz/98=") -> #REF! | HQ3: =AND('Author and Rec of Changes'!#REF!,"AAAAABPz/+A=") -> #REF! | HR3: =AND('Author and Rec of Changes'!#REF!,"AAAAABPz/+E=") -> #REF! | HS3: =AND('Author and Rec of Changes'!#REF!,"AAAAABPz/+I=") -> #REF! | HT3: =AND('Author and Rec of Changes'!#REF!,"AAAAABPz/+M=") -> #REF! | HU3: =AND('Author and Rec of Changes'!#REF!,"AAAAABPz/+Q=") -> #REF! | HV3: =IF('Author and Rec of Changes'!5:5,"AAAAABPz/+U=",0) -> 0 | HW3: =AND('Author and Rec of Changes'!A5,"AAAAABPz/+Y=") -> #VALUE! | HX3: =AND('Author and Rec of Changes'!B5,"AAAAABPz/+c=") -> #VALUE! | HY3: =AND('Author and Rec of Changes'!C5,"AAAAABPz/+g=") -> #VALUE! | HZ3: =AND('Author and Rec of Changes'!E5,"AAAAABPz/+k=") -> #VALUE! | IA3: =AND('Author and Rec of Changes'!F5,"AAAAABPz/+o=") -> #VALUE! | IB3: =AND('Author and Rec of Changes'!#REF!,"AAAAABPz/+s=") -> #REF! | IC3: =IF('Author and Rec of Changes'!#REF!,"AAAAABPz/+w=",0) -> #REF! | ID3: =AND('Author and Rec of Changes'!#REF!,"AAAAABPz/+0=") -> #REF! | IE3: =AND('Author and Rec of Changes'!#REF!,"AAAAABPz/+4=") -> #REF! | IF3: =AND('Author and Rec of Changes'!#REF!,"AAAAABPz/+8=") -> #REF! | IG3: =AND('Author and Rec of Changes'!#REF!,"AAAAABPz//A=") -> #REF! | IH3: =AND('Author and Rec of Changes'!#REF!,"AAAAABPz//E=") -> #REF! | II3: =AND('Author and Rec of Changes'!#REF!,"AAAAABPz//I=") -> #REF! | IJ3: =IF('Author and Rec of Changes'!#REF!,"AAAAABPz//M=",0) -> #REF! | IK3: =AND('Author and Rec of Changes'!#REF!,"AAAAABPz//Q=") -> #REF! | IL3: =AND('Author and Rec of Changes'!#REF!,"AAAAABPz//U=") -> #REF! | IM3: =AND('Author and Rec of Changes'!#REF!,"AAAAABPz//Y=") -> #REF! | IN3: =AND('Author and Rec of Changes'!#REF!,"AAAAABPz//c=") -> #REF! | IO3: =AND('Author and Rec of Changes'!#REF!,"AAAAABPz//g=") -> #REF! | IP3: =AND('Author and Rec of Changes'!#REF!,"AAAAABPz//k=") -> #REF! | IQ3: =IF('Author and Rec of Changes'!6:6,"AAAAABPz//o=",0) -> 0 | IR3: =AND('Author and Rec of Changes'!A6,"AAAAABPz//s=") -> #VALUE! | IS3: =AND('Author and Rec of Changes'!B6,"AAAAABPz//w=") -> #VALUE! | IT3: =AND('Author and Rec of Changes'!C6,"AAAAABPz//0=") -> #VALUE! | IU3: =AND('Author and Rec of Changes'!E6,"AAAAABPz//4=") -> #VALUE! | IV3: =AND('Author and Rec of Changes'!F6,"AAAAABPz//8=") -> #VALUE!
